  File "manage.py", line 14
    ) from exc
         ^
SyntaxError: invalid syntax
Unknown command: 'runserver8000'. Did you mean runserver?
Type 'manage.py help' for usage.
Not Found: /crawling/tagnum/pictures/3
[11/Oct/2018 08:39:01] "GET /crawling/tagnum/pictures/3 HTTP/1.1" 404 2302
Not Found: /favicon.ico
[11/Oct/2018 08:39:01] "GET /favicon.ico HTTP/1.1" 404 2257
Not Found: /crawling/tagnum/3
[11/Oct/2018 08:39:11] "GET /crawling/tagnum/3 HTTP/1.1" 404 2275
Not Found: /favicon.ico
[11/Oct/2018 08:39:11] "GET /favicon.ico HTTP/1.1" 404 2257
Performing system checks...

System check identified no issues (0 silenced).
October 11, 2018 - 08:38:09
Django version 2.1.2, using settings 'pospot.settings'
Starting development server at http://0.0.0.0:8000/
Quit the server with CONTROL-C.
Internal Server Error: /crawling/tagnum/3
Traceback (most recent call last):
  File "/home/pospot/Env/pospot/lib/python3.6/site-packages/django/core/handlers/exception.py", line 34, in inner
    response = get_response(request)
  File "/home/pospot/Env/pospot/lib/python3.6/site-packages/django/core/handlers/base.py", line 126, in _get_response
    response = self.process_exception_by_middleware(e, request)
  File "/home/pospot/Env/pospot/lib/python3.6/site-packages/django/core/handlers/base.py", line 124, in _get_response
    response = wrapped_callback(request, *callback_args, **callback_kwargs)
  File "/home/pospot/pospot/crawling/views.py", line 8, in tagnum
    driver = webdriver.Chrome('chrome/chromedriver')
  File "/home/pospot/Env/pospot/lib/python3.6/site-packages/selenium/webdriver/chrome/webdriver.py", line 73, in __init__
    self.service.start()
  File "/home/pospot/Env/pospot/lib/python3.6/site-packages/selenium/webdriver/common/service.py", line 76, in start
    stdin=PIPE)
  File "/usr/lib/python3.6/subprocess.py", line 709, in __init__
    restore_signals, start_new_session)
  File "/usr/lib/python3.6/subprocess.py", line 1344, in _execute_child
    raise child_exception_type(errno_num, err_msg, err_filename)
OSError: [Errno 8] Exec format error: 'chrome/chromedriver'
[11/Oct/2018 08:39:52] "GET /crawling/tagnum/3 HTTP/1.1" 500 101170
Internal Server Error: /crawling/tagnum/
Traceback (most recent call last):
  File "/home/pospot/Env/pospot/lib/python3.6/site-packages/django/core/handlers/exception.py", line 34, in inner
    response = get_response(request)
  File "/home/pospot/Env/pospot/lib/python3.6/site-packages/django/core/handlers/base.py", line 126, in _get_response
    response = self.process_exception_by_middleware(e, request)
  File "/home/pospot/Env/pospot/lib/python3.6/site-packages/django/core/handlers/base.py", line 124, in _get_response
    response = wrapped_callback(request, *callback_args, **callback_kwargs)
  File "/home/pospot/pospot/crawling/views.py", line 8, in tagnum
    driver = webdriver.Chrome('chrome/chromedriver')
  File "/home/pospot/Env/pospot/lib/python3.6/site-packages/selenium/webdriver/chrome/webdriver.py", line 73, in __init__
    self.service.start()
  File "/home/pospot/Env/pospot/lib/python3.6/site-packages/selenium/webdriver/common/service.py", line 76, in start
    stdin=PIPE)
  File "/usr/lib/python3.6/subprocess.py", line 709, in __init__
    restore_signals, start_new_session)
  File "/usr/lib/python3.6/subprocess.py", line 1344, in _execute_child
    raise child_exception_type(errno_num, err_msg, err_filename)
OSError: [Errno 8] Exec format error: 'chrome/chromedriver'
[11/Oct/2018 08:40:18] "GET /crawling/tagnum/ HTTP/1.1" 500 101159
Internal Server Error: /crawling/pictures
Traceback (most recent call last):
  File "/home/pospot/Env/pospot/lib/python3.6/site-packages/django/core/handlers/exception.py", line 34, in inner
    response = get_response(request)
  File "/home/pospot/Env/pospot/lib/python3.6/site-packages/django/core/handlers/base.py", line 126, in _get_response
    response = self.process_exception_by_middleware(e, request)
  File "/home/pospot/Env/pospot/lib/python3.6/site-packages/django/core/handlers/base.py", line 124, in _get_response
    response = wrapped_callback(request, *callback_args, **callback_kwargs)
TypeError: tagnum() missing 1 required positional argument: 'pk'
[11/Oct/2018 08:40:19] "GET /crawling/pictures HTTP/1.1" 500 59487
Internal Server Error: /crawling/pictures
Traceback (most recent call last):
  File "/home/pospot/Env/pospot/lib/python3.6/site-packages/django/core/handlers/exception.py", line 34, in inner
    response = get_response(request)
  File "/home/pospot/Env/pospot/lib/python3.6/site-packages/django/core/handlers/base.py", line 126, in _get_response
    response = self.process_exception_by_middleware(e, request)
  File "/home/pospot/Env/pospot/lib/python3.6/site-packages/django/core/handlers/base.py", line 124, in _get_response
    response = wrapped_callback(request, *callback_args, **callback_kwargs)
TypeError: tagnum() missing 1 required positional argument: 'pk'
[11/Oct/2018 08:40:24] "GET /crawling/pictures HTTP/1.1" 500 59487
Internal Server Error: /crawling/pictures
Traceback (most recent call last):
  File "/home/pospot/Env/pospot/lib/python3.6/site-packages/django/core/handlers/exception.py", line 34, in inner
    response = get_response(request)
  File "/home/pospot/Env/pospot/lib/python3.6/site-packages/django/core/handlers/base.py", line 126, in _get_response
    response = self.process_exception_by_middleware(e, request)
  File "/home/pospot/Env/pospot/lib/python3.6/site-packages/django/core/handlers/base.py", line 124, in _get_response
    response = wrapped_callback(request, *callback_args, **callback_kwargs)
TypeError: tagnum() missing 1 required positional argument: 'pk'
[11/Oct/2018 08:40:25] "GET /crawling/pictures HTTP/1.1" 500 59487
Internal Server Error: /crawling/pictures/3
Traceback (most recent call last):
  File "/home/pospot/Env/pospot/lib/python3.6/site-packages/django/core/handlers/exception.py", line 34, in inner
    response = get_response(request)
  File "/home/pospot/Env/pospot/lib/python3.6/site-packages/django/core/handlers/base.py", line 126, in _get_response
    response = self.process_exception_by_middleware(e, request)
  File "/home/pospot/Env/pospot/lib/python3.6/site-packages/django/core/handlers/base.py", line 124, in _get_response
    response = wrapped_callback(request, *callback_args, **callback_kwargs)
TypeError: tagnum() missing 1 required positional argument: 'pk'
[11/Oct/2018 08:40:36] "GET /crawling/pictures/3 HTTP/1.1" 500 59507
Not Found: /favicon.ico
[11/Oct/2018 08:40:37] "GET /favicon.ico HTTP/1.1" 404 2256
Internal Server Error: /crawling/pictures/3
Traceback (most recent call last):
  File "/home/pospot/Env/pospot/lib/python3.6/site-packages/django/core/handlers/exception.py", line 34, in inner
    response = get_response(request)
  File "/home/pospot/Env/pospot/lib/python3.6/site-packages/django/core/handlers/base.py", line 126, in _get_response
    response = self.process_exception_by_middleware(e, request)
  File "/home/pospot/Env/pospot/lib/python3.6/site-packages/django/core/handlers/base.py", line 124, in _get_response
    response = wrapped_callback(request, *callback_args, **callback_kwargs)
TypeError: tagnum() missing 1 required positional argument: 'pk'
[11/Oct/2018 08:41:33] "GET /crawling/pictures/3 HTTP/1.1" 500 59507
Performing system checks...

System check identified no issues (0 silenced).
October 11, 2018 - 08:39:49
Django version 2.1.2, using settings 'pospot.settings'
Starting development server at http://0.0.0.0:8000/
Quit the server with CONTROL-C.
Performing system checks...

System check identified no issues (0 silenced).
October 11, 2018 - 08:42:21
Django version 2.1.2, using settings 'pospot.settings'
Starting development server at http://0.0.0.0:8000/
Quit the server with CONTROL-C.
Traceback (most recent call last):
  File "manage.py", line 8, in <module>
    from django.core.management import execute_from_command_line
ModuleNotFoundError: No module named 'django'

The above exception was the direct cause of the following exception:

Traceback (most recent call last):
  File "manage.py", line 14, in <module>
    ) from exc
ImportError: Couldn't import Django. Are you sure it's installed and available on your PYTHONPATH environment variable? Did you forget to activate a virtual environment?
Traceback (most recent call last):
  File "manage.py", line 8, in <module>
    from django.core.management import execute_from_command_line
ModuleNotFoundError: No module named 'django'

The above exception was the direct cause of the following exception:

Traceback (most recent call last):
  File "manage.py", line 14, in <module>
    ) from exc
ImportError: Couldn't import Django. Are you sure it's installed and available on your PYTHONPATH environment variable? Did you forget to activate a virtual environment?
Internal Server Error: /crawling/pictures
Traceback (most recent call last):
  File "/home/pospot/Env/pospot/lib/python3.6/site-packages/django/core/handlers/exception.py", line 34, in inner
    response = get_response(request)
  File "/home/pospot/Env/pospot/lib/python3.6/site-packages/django/core/handlers/base.py", line 126, in _get_response
    response = self.process_exception_by_middleware(e, request)
  File "/home/pospot/Env/pospot/lib/python3.6/site-packages/django/core/handlers/base.py", line 124, in _get_response
    response = wrapped_callback(request, *callback_args, **callback_kwargs)
TypeError: tagnum() missing 1 required positional argument: 'pk'
[11/Oct/2018 09:25:18] "GET /crawling/pictures HTTP/1.1" 500 60829
Not Found: /favicon.ico
[11/Oct/2018 09:25:18] "GET /favicon.ico HTTP/1.1" 404 2256
Performing system checks...

System check identified no issues (0 silenced).
October 11, 2018 - 09:24:38
Django version 2.1.2, using settings 'pospot.settings'
Starting development server at http://0.0.0.0:8000/
Quit the server with CONTROL-C.
Internal Server Error: /crawling/pictures
Traceback (most recent call last):
  File "/home/pospot/Env/pospot/lib/python3.6/site-packages/django/core/handlers/exception.py", line 34, in inner
    response = get_response(request)
  File "/home/pospot/Env/pospot/lib/python3.6/site-packages/django/core/handlers/base.py", line 126, in _get_response
    response = self.process_exception_by_middleware(e, request)
  File "/home/pospot/Env/pospot/lib/python3.6/site-packages/django/core/handlers/base.py", line 124, in _get_response
    response = wrapped_callback(request, *callback_args, **callback_kwargs)
TypeError: tagnum() missing 1 required positional argument: 'pk'
[11/Oct/2018 09:27:31] "GET /crawling/pictures HTTP/1.1" 500 60964
Performing system checks...

System check identified no issues (0 silenced).
October 11, 2018 - 09:26:29
Django version 2.1.2, using settings 'pospot.settings'
Starting development server at http://0.0.0.0:8000/
Quit the server with CONTROL-C.
Performing system checks...

System check identified no issues (0 silenced).
October 11, 2018 - 09:27:40
Django version 2.1.2, using settings 'pospot.settings'
Starting development server at http://0.0.0.0:8000/
Quit the server with CONTROL-C.
Performing system checks...

System check identified no issues (0 silenced).
October 11, 2018 - 09:27:58
Django version 2.1.2, using settings 'pospot.settings'
Starting development server at http://0.0.0.0:8000/
Quit the server with CONTROL-C.
[11/Oct/2018 09:28:28] "GET /crawling/pictures HTTP/1.1" 200 18
Internal Server Error: /crawling/tagnum/3
Traceback (most recent call last):
  File "/home/pospot/Env/pospot/lib/python3.6/site-packages/django/core/handlers/exception.py", line 34, in inner
    response = get_response(request)
  File "/home/pospot/Env/pospot/lib/python3.6/site-packages/django/core/handlers/base.py", line 126, in _get_response
    response = self.process_exception_by_middleware(e, request)
  File "/home/pospot/Env/pospot/lib/python3.6/site-packages/django/core/handlers/base.py", line 124, in _get_response
    response = wrapped_callback(request, *callback_args, **callback_kwargs)
  File "/home/pospot/pospot/crawling/views.py", line 9, in tagnum
    driver = webdriver.Chrome(os.getcwd(),timeout)
NameError: name 'timeout' is not defined
[11/Oct/2018 09:28:33] "GET /crawling/tagnum/3 HTTP/1.1" 500 64508
Performing system checks...

System check identified no issues (0 silenced).
October 11, 2018 - 09:28:26
Django version 2.1.2, using settings 'pospot.settings'
Starting development server at http://0.0.0.0:8000/
Quit the server with CONTROL-C.
Unhandled exception in thread started by <function check_errors.<locals>.wrapper at 0x7f96aec1a158>
Traceback (most recent call last):
  File "/home/pospot/Env/pospot/lib/python3.6/site-packages/django/utils/autoreload.py", line 225, in wrapper
    fn(*args, **kwargs)
  File "/home/pospot/Env/pospot/lib/python3.6/site-packages/django/core/management/commands/runserver.py", line 117, in inner_run
    self.check(display_num_errors=True)
  File "/home/pospot/Env/pospot/lib/python3.6/site-packages/django/core/management/base.py", line 379, in check
    include_deployment_checks=include_deployment_checks,
  File "/home/pospot/Env/pospot/lib/python3.6/site-packages/django/core/management/base.py", line 366, in _run_checks
    return checks.run_checks(**kwargs)
  File "/home/pospot/Env/pospot/lib/python3.6/site-packages/django/core/checks/registry.py", line 71, in run_checks
    new_errors = check(app_configs=app_configs)
  File "/home/pospot/Env/pospot/lib/python3.6/site-packages/django/core/checks/urls.py", line 13, in check_url_config
    return check_resolver(resolver)
  File "/home/pospot/Env/pospot/lib/python3.6/site-packages/django/core/checks/urls.py", line 23, in check_resolver
    return check_method()
  File "/home/pospot/Env/pospot/lib/python3.6/site-packages/django/urls/resolvers.py", line 396, in check
    for pattern in self.url_patterns:
  File "/home/pospot/Env/pospot/lib/python3.6/site-packages/django/utils/functional.py", line 37, in __get__
    res = instance.__dict__[self.name] = self.func(instance)
  File "/home/pospot/Env/pospot/lib/python3.6/site-packages/django/urls/resolvers.py", line 533, in url_patterns
    patterns = getattr(self.urlconf_module, "urlpatterns", self.urlconf_module)
  File "/home/pospot/Env/pospot/lib/python3.6/site-packages/django/utils/functional.py", line 37, in __get__
    res = instance.__dict__[self.name] = self.func(instance)
  File "/home/pospot/Env/pospot/lib/python3.6/site-packages/django/urls/resolvers.py", line 526, in urlconf_module
    return import_module(self.urlconf_name)
  File "/home/pospot/Env/pospot/lib/python3.6/importlib/__init__.py", line 126, in import_module
    return _bootstrap._gcd_import(name[level:], package, level)
  File "<frozen importlib._bootstrap>", line 994, in _gcd_import
  File "<frozen importlib._bootstrap>", line 971, in _find_and_load
  File "<frozen importlib._bootstrap>", line 955, in _find_and_load_unlocked
  File "<frozen importlib._bootstrap>", line 665, in _load_unlocked
  File "<frozen importlib._bootstrap_external>", line 678, in exec_module
  File "<frozen importlib._bootstrap>", line 219, in _call_with_frames_removed
  File "/home/pospot/pospot/pospot/urls.py", line 19, in <module>
    from crawling import views
  File "/home/pospot/pospot/crawling/views.py", line 10
    driver.set_page_load_timeout(my_timeout_secs)
         ^
SyntaxError: invalid syntax
Performing system checks...

[11/Oct/2018 09:29:54] "GET /crawling/pictures HTTP/1.1" 200 18
Internal Server Error: /crawling/tagnum/3
Traceback (most recent call last):
  File "/home/pospot/Env/pospot/lib/python3.6/site-packages/selenium/webdriver/common/service.py", line 76, in start
    stdin=PIPE)
  File "/usr/lib/python3.6/subprocess.py", line 709, in __init__
    restore_signals, start_new_session)
  File "/usr/lib/python3.6/subprocess.py", line 1344, in _execute_child
    raise child_exception_type(errno_num, err_msg, err_filename)
PermissionError: [Errno 13] Permission denied: '/home/pospot/pospot'

During handling of the above exception, another exception occurred:

Traceback (most recent call last):
  File "/home/pospot/Env/pospot/lib/python3.6/site-packages/django/core/handlers/exception.py", line 34, in inner
    response = get_response(request)
  File "/home/pospot/Env/pospot/lib/python3.6/site-packages/django/core/handlers/base.py", line 126, in _get_response
    response = self.process_exception_by_middleware(e, request)
  File "/home/pospot/Env/pospot/lib/python3.6/site-packages/django/core/handlers/base.py", line 124, in _get_response
    response = wrapped_callback(request, *callback_args, **callback_kwargs)
  File "/home/pospot/pospot/crawling/views.py", line 9, in tagnum
    driver = webdriver.Chrome(os.getcwd())
  File "/home/pospot/Env/pospot/lib/python3.6/site-packages/selenium/webdriver/chrome/webdriver.py", line 73, in __init__
    self.service.start()
  File "/home/pospot/Env/pospot/lib/python3.6/site-packages/selenium/webdriver/common/service.py", line 88, in start
    os.path.basename(self.path), self.start_error_message)
selenium.common.exceptions.WebDriverException: Message: 'pospot' executable may have wrong permissions. Please see https://sites.google.com/a/chromium.org/chromedriver/home

[11/Oct/2018 09:29:59] "GET /crawling/tagnum/3 HTTP/1.1" 500 108983
